Workbook

Sheet Cover Page
B6: MOBILE WORLD GROUP
B7: Ticker: MWG
B8: Nov 20, 2025
B19: Presented by: Nguyen Quoc Anh

Sheet Executive Summary
F1: MOBILE WORLD INVESTMENT CORPORATION
H2: SUMMARY OUTPUT
H4: SUMMARY VALUES - BASE CASE
N5: PROJECTED
B6: Billion VND | C6: Trend | E6: 2018 | F6: 2019 | G6: 2020 | H6: 2021 | I6: 2022 | J6: 2023 | K6: 2024 | L6: 2025 | M6: 2026 | N6: 2027 | O6: 2028 | P6: 2029 | Q6: 2030
B7: Income Statement Items
B8: Net Revenue | E8: {=TRANSPOSE('Breakdown by Segments'!F6:F13)} -> 86516 | F8: 102174 | G8: 108546 | H8: 122958 | I8: 133405 | J8: 118280 | K8: 134341 | L8: =K8*(1+'DCF Model'!K34) -> 153923.28 | M8: =L8*(1+'DCF Model'!L34) -> 178197.46 | N8: =M8*(1+'DCF Model'!M34) -> 203413.85 | O8: =N8*(1+'DCF Model'!N34) -> 233447.14 | P8: =O8*(1+'DCF Model'!O34) -> 273991.17 | Q8: =P8*(1+'DCF Model'!P34) -> 337888.1
B9: Growth | F9: ='DCF Model'!E34 -> 0.18098277 | G9: ='DCF Model'!F34 -> 0.062361858 | H9: ='DCF Model'!G34 -> 0.13277397 | I9: ='DCF Model'!H34 -> 0.084961226 | J9: ='DCF Model'!I34 -> -0.11337667 | K9: ='DCF Model'!J34 -> 0.13579128 | L9: ='DCF Model'!K36 -> 0.1457655 | M9: ='DCF Model'!L36 -> 0.15770305 | N9: ='DCF Model'!M36 -> 0.14150817 | O9: ='DCF Model'!N36 -> 0.14764625 | P9: ='DCF Model'!O36 -> 0.17367538 | Q9: ='DCF Model'!P36 -> 0.23320801
B10: EBIT Margin | E10: ='DCF Model'!D43 -> 0.043016323 | F10: ='DCF Model'!E43 -> 0.048651313 | G10: ='DCF Model'!F43 -> 0.049293881 | H10: ='DCF Model'!G43 -> 0.052082548 | I10: ='DCF Model'!H43 -> 0.04880184 | J10: ='DCF Model'!I43 -> 0.008781612 | K10: ='DCF Model'!J43 -> 0.038654402 | L10: ='DCF Model'!K45 -> 0.041325988 | M10: ='DCF Model'!L45 -> 0.041084512 | N10: ='DCF Model'!M45 -> 0.040003541 | O10: ='DCF Model'!N45 -> 0.038676349 | P10: ='DCF Model'!O45 -> 0.036761178 | Q10: ='DCF Model'!P45 -> 0.035041083
B11: Growth | F11: ='DCF Model'!E42/'DCF Model'!D42-1 -> 0.33397989 | G11: ='DCF Model'!F42/'DCF Model'!E42-1 -> 0.075048711 | H11: ='DCF Model'!G42/'DCF Model'!F42-1 -> 0.1945628 | I11: ='DCF Model'!H42/'DCF Model'!G42-1 -> 0.016871855 | J11: ='DCF Model'!I42/'DCF Model'!H42-1 -> -0.84074264 | K11: ='DCF Model'!J42/'DCF Model'!I42-1 -> 3.9920766 | L11: =('DCF Model'!K30*'DCF Model'!K45)/('DCF Model'!J30*'DCF Model'!J43)-1 -> 0.22495471 | M11: =('DCF Model'!L30*'DCF Model'!L45)/('DCF Model'!K30*'DCF Model'!K45)-1 -> 0.15093836 | N11: =('DCF Model'!M30*'DCF Model'!M45)/('DCF Model'!L30*'DCF Model'!L45)-1 -> 0.11147403 | O11: =('DCF Model'!N30*'DCF Model'!N45)/('DCF Model'!M30*'DCF Model'!M45)-1 -> 0.10957097 | P11: =('DCF Model'!O30*'DCF Model'!O45)/('DCF Model'!N30*'DCF Model'!N45)-1 -> 0.11555745 | Q11: =('DCF Model'!P30*'DCF Model'!P45)/('DCF Model'!O30*'DCF Model'!O45)-1 -> 0.17550489
B12: EBIAT Margin | E12: ='DCF Model'!D52 -> 0.032372899 | F12: ='DCF Model'!E52 -> 0.036588188 | G12: ='DCF Model'!F52 -> 0.034736544 | H12: ='DCF Model'!G52 -> 0.038928402 | I12: ='DCF Model'!H52 -> 0.035492986 | J12: ='DCF Model'!I52 -> 0.0051479463 | K12: ='DCF Model'!J52 -> 0.029169942 | L12: ='DCF Model'!K54 -> 0.02966546 | M12: ='DCF Model'!L54 -> 0.029288268 | N12: ='DCF Model'!M54 -> 0.028293814 | O12: ='DCF Model'!N54 -> 0.02736948 | P12: ='DCF Model'!O54 -> 0.02580528 | Q12: ='DCF Model'!P54 -> 0.024471091
B13: Growth | F13: ='DCF Model'!E51/'DCF Model'!D51-1 -> 0.33305266 | G13: ='DCF Model'!F51/'DCF Model'!E51-1 -> 0.007338441 | H13: ='DCF Model'!G51/'DCF Model'!F51-1 -> 0.26703831 | I13: ='DCF Model'!H51/'DCF Model'!G51-1 -> -0.010540083 | J13: ='DCF Model'!I51/'DCF Model'!H51-1 -> -0.87163314 | K13: ='DCF Model'!J51/'DCF Model'!I51-1 -> 5.4262569 | L13: =('DCF Model'!K30*'DCF Model'!K54)/'DCF Model'!J51-1 -> 0.16522897 | M13: =('DCF Model'!L30*'DCF Model'!L54)/('DCF Model'!K30*'DCF Model'!K54)-1 -> 0.14298304 | N13: =('DCF Model'!M30*'DCF Model'!M54)/('DCF Model'!L30*'DCF Model'!L54)-1 -> 0.10274939 | O13: =('DCF Model'!N30*'DCF Model'!N54)/('DCF Model'!M30*'DCF Model'!M54)-1 -> 0.11015367 | P13: =('DCF Model'!O30*'DCF Model'!O54)/('DCF Model'!N30*'DCF Model'!N54)-1 -> 0.10659836 | Q13: =('DCF Model'!P30*'DCF Model'!P54)/('DCF Model'!O30*'DCF Model'!O54)-1 -> 0.16944845
H18: SUMMARY VALUES - OPTIMISTIC CASE
N19: PROJECTED
B20: Billion VND | C20: Trend | E20: 2018 | F20: 2019 | G20: 2020 | H20: 2021 | I20: 2022 | J20: 2023 | K20: 2024 | L20: 2025 | M20: 2026 | N20: 2027 | O20: 2028 | P20: 2029 | Q20: 2030
B21: Income Statement Items
B22: Net Revenue | E22: {=TRANSPOSE('Breakdown by Segments'!F6:F14)} -> 86516 | F22: 102174 | G22: 108546 | H22: 122958 | I22: 133405 | J22: 118280 | K22: 134341 | L22: =K22*(1+'DCF Model'!K37) -> 154902.4 | M22: =L22*(1+'DCF Model'!L37) -> 180552.41 | N22: =M22*(1+'DCF Model'!M37) -> 207379.53 | O22: =N22*(1+'DCF Model'!N37) -> 239529.28 | P22: =O22*(1+'DCF Model'!O37) -> 283209.64 | Q22: =P22*(1+'DCF Model'!P37) -> 352558.73
B23: Growth | F23: ='DCF Model'!E34 -> 0.18098277 | G23: ='DCF Model'!F34 -> 0.062361858 | H23: ='DCF Model'!G34 -> 0.13277397 | I23: ='DCF Model'!H34 -> 0.084961226 | J23: ='DCF Model'!I34 -> -0.11337667 | K23: ='DCF Model'!J34 -> 0.13579128 | L23: ='DCF Model'!K37 -> 0.15305378 | M23: ='DCF Model'!L37 -> 0.16558821 | N23: ='DCF Model'!M37 -> 0.14858358 | O23: ='DCF Model'!N37 -> 0.15502857 | P23: ='DCF Model'!O37 -> 0.18235915 | Q23: ='DCF Model'!P37 -> 0.24486841
B24: EBIT Margin | E24: ='DCF Model'!D43 -> 0.043016323 | F24: ='DCF Model'!E43 -> 0.048651313 | G24: ='DCF Model'!F43 -> 0.049293881 | H24: ='DCF Model'!G43 -> 0.052082548 | I24: ='DCF Model'!H43 -> 0.04880184 | J24: ='DCF Model'!I43 -> 0.008781612 | K24: ='DCF Model'!J43 -> 0.038654402 | L24: ='DCF Model'!K46 -> 0.043392288 | M24: ='DCF Model'!L46 -> 0.043138738 | N24: ='DCF Model'!M46 -> 0.042003718 | O24: ='DCF Model'!N46 -> 0.040610166 | P24: ='DCF Model'!O46 -> 0.038599237 | Q24: ='DCF Model'!P46 -> 0.036793137
B25: Growth | F25: ='DCF Model'!E42/'DCF Model'!D42-1 -> 0.33397989 | G25: ='DCF Model'!F42/'DCF Model'!E42-1 -> 0.075048711 | H25: ='DCF Model'!G42/'DCF Model'!F42-1 -> 0.1945628 | I25: ='DCF Model'!H42/'DCF Model'!G42-1 -> 0.016871855 | J25: ='DCF Model'!I42/'DCF Model'!H42-1 -> -0.84074264 | K25: ='DCF Model'!J42/'DCF Model'!I42-1 -> 3.9920766 | L25: =('DCF Model'!K30*'DCF Model'!K46)/'DCF Model'!J42-1 -> 0.28620245 | M25: =('DCF Model'!L30*'DCF Model'!L46)/('DCF Model'!K30*'DCF Model'!K46)-1 -> 0.15093836 | N25: =('DCF Model'!M30*'DCF Model'!M46)/('DCF Model'!L30*'DCF Model'!L46)-1 -> 0.11147403 | O25: =('DCF Model'!N30*'DCF Model'!N46)/('DCF Model'!M30*'DCF Model'!M46)-1 -> 0.10957097 | P25: =('DCF Model'!O30*'DCF Model'!O46)/('DCF Model'!N30*'DCF Model'!N46)-1 -> 0.11555745 | Q25: =('DCF Model'!P30*'DCF Model'!P46)/('DCF Model'!O30*'DCF Model'!O46)-1 -> 0.17550489
B26: EBIAT Margin | E26: ='DCF Model'!D52 -> 0.032372899 | F26: ='DCF Model'!E52 -> 0.036588188 | G26: ='DCF Model'!F52 -> 0.034736544 | H26: ='DCF Model'!G52 -> 0.038928402 | I26: ='DCF Model'!H52 -> 0.035492986 | J26: ='DCF Model'!I52 -> 0.0051479463 | K26: ='DCF Model'!J52 -> 0.029169942 | L26: ='DCF Model'!K55 -> 0.031148733 | M26: ='DCF Model'!L55 -> 0.030752682 | N26: ='DCF Model'!M55 -> 0.029708505 | O26: ='DCF Model'!N55 -> 0.028737954 | P26: ='DCF Model'!O55 -> 0.027095544 | Q26: ='DCF Model'!P55 -> 0.025694645
B27: Growth | F27: ='DCF Model'!E51/'DCF Model'!D51-1 -> 0.33305266 | G27: ='DCF Model'!F51/'DCF Model'!E51-1 -> 0.007338441 | H27: ='DCF Model'!G51/'DCF Model'!F51-1 -> 0.26703831 | I27: ='DCF Model'!H51/'DCF Model'!G51-1 -> -0.010540083 | J27: ='DCF Model'!I51/'DCF Model'!H51-1 -> -0.87163314 | K27: ='DCF Model'!J51/'DCF Model'!I51-1 -> 5.4262569 | L27: =('DCF Model'!K30*'DCF Model'!K55)/'DCF Model'!J51-1 -> 0.22349041 | M27: =('DCF Model'!L30*'DCF Model'!L55)/('DCF Model'!K30*'DCF Model'!K55)-1 -> 0.14298304 | N27: =('DCF Model'!M30*'DCF Model'!M55)/('DCF Model'!L30*'DCF Model'!L55)-1 -> 0.10274939 | O27: =('DCF Model'!N30*'DCF Model'!N55)/('DCF Model'!M30*'DCF Model'!M55)-1 -> 0.11015367 | P27: =('DCF Model'!O30*'DCF Model'!O55)/('DCF Model'!N30*'DCF Model'!N55)-1 -> 0.10659836 | Q27: =('DCF Model'!P30*'DCF Model'!P55)/('DCF Model'!O30*'DCF Model'!O55)-1 -> 0.16944845
H32: SUMMARY VALUES - PESSIMISTIC CASE
N33: PROJECTED
B34: Billion VND | C34: Trend | E34: 2018 | F34: 2019 | G34: 2020 | H34: 2021 | I34: 2022 | J34: 2023 | K34: 2024 | L34: 2025 | M34: 2026 | N34: 2027 | O34: 2028 | P34: 2029 | Q34: 2030
B35: Income Statement Items
B36: Net Revenue | E36: {=TRANSPOSE('Breakdown by Segments'!F6:F13)} -> 86516 | F36: 102174 | G36: 108546 | H36: 122958 | I36: 133405 | J36: 118280 | K36: 134341 | L36: =K36*(1+'DCF Model'!K35) -> 151965.06 | M36: =L36*(1+'DCF Model'!L31) -> 175930.41 | N36: =M36*(1+'DCF Model'!M31) -> 200826 | O36: =N36*(1+'DCF Model'!N31) -> 230477.21 | P36: =O36*(1+'DCF Model'!O31) -> 270505.42 | Q36: =P36*(1+'DCF Model'!P31) -> 333589.45
B37: Growth | F37: ='DCF Model'!E31 -> 0.17947297 | G37: ='DCF Model'!F31 -> 0.061034973 | H37: ='DCF Model'!G31 -> 0.13060208 | I37: ='DCF Model'!H31 -> 0.085231136 | J37: ='DCF Model'!I31 -> -0.11496293 | K37: ='DCF Model'!J31 -> 0.13411352 | L37: ='DCF Model'!K35 -> 0.13118895 | M37: ='DCF Model'!L35 -> 0.14193275 | N37: ='DCF Model'!M35 -> 0.12735736 | O37: ='DCF Model'!N35 -> 0.13288163 | P37: ='DCF Model'!O35 -> 0.15630784 | Q37: ='DCF Model'!P35 -> 0.20988721
B38: EBIT Margin | E38: ='DCF Model'!D43 -> 0.043016323 | F38: ='DCF Model'!E43 -> 0.048651313 | G38: ='DCF Model'!F43 -> 0.049293881 | H38: ='DCF Model'!G43 -> 0.052082548 | I38: ='DCF Model'!H43 -> 0.04880184 | J38: ='DCF Model'!I43 -> 0.008781612 | K38: ='DCF Model'!J43 -> 0.038654402 | L38: ='DCF Model'!K44 -> 0.03719339 | M38: ='DCF Model'!L44 -> 0.036976061 | N38: ='DCF Model'!M44 -> 0.036003186 | O38: ='DCF Model'!N44 -> 0.034808714 | P38: ='DCF Model'!O44 -> 0.03308506 | Q38: ='DCF Model'!P44 -> 0.031536975
B39: Growth | F39: ='DCF Model'!E42/'DCF Model'!D42-1 -> 0.33397989 | G39: ='DCF Model'!F42/'DCF Model'!E42-1 -> 0.075048711 | H39: ='DCF Model'!G42/'DCF Model'!F42-1 -> 0.1945628 | I39: ='DCF Model'!H42/'DCF Model'!G42-1 -> 0.016871855 | J39: ='DCF Model'!I42/'DCF Model'!H42-1 -> -0.84074264 | K39: ='DCF Model'!J42/'DCF Model'!I42-1 -> 3.9920766 | L39: =('DCF Model'!K30*'DCF Model'!K44)/'DCF Model'!J42-1 -> 0.10245924 | M39: =('DCF Model'!L30*'DCF Model'!L44)/('DCF Model'!K30*'DCF Model'!K44)-1 -> 0.15093836 | N39: =('DCF Model'!M30*'DCF Model'!M44)/('DCF Model'!L30*'DCF Model'!L44)-1 -> 0.11147403 | O39: =('DCF Model'!N30*'DCF Model'!N44)/('DCF Model'!M30*'DCF Model'!M44)-1 -> 0.10957097 | P39: =('DCF Model'!O30*'DCF Model'!O44)/('DCF Model'!N30*'DCF Model'!N44)-1 -> 0.11555745 | Q39: =('DCF Model'!P30*'DCF Model'!P44)/('DCF Model'!O30*'DCF Model'!O44)-1 -> 0.17550489
B40: EBIAT Margin | E40: ='DCF Model'!D52 -> 0.032372899 | F40: ='DCF Model'!E52 -> 0.036588188 | G40: ='DCF Model'!F52 -> 0.034736544 | H40: ='DCF Model'!G52 -> 0.038928402 | I40: ='DCF Model'!H52 -> 0.035492986 | J40: ='DCF Model'!I52 -> 0.0051479463 | K40: ='DCF Model'!J52 -> 0.029169942 | L40: ='DCF Model'!K53 -> 0.026698914 | M40: ='DCF Model'!L53 -> 0.026359442 | N40: ='DCF Model'!M53 -> 0.025464433 | O40: ='DCF Model'!N53 -> 0.024632532 | P40: ='DCF Model'!O53 -> 0.023224752 | Q40: ='DCF Model'!P53 -> 0.022023982
B41: Growth | F41: =F40/E40-1 -> 0.13021043 | G41: =G40/F40-1 -> -0.050607693 | H41: =H40/G40-1 -> 0.12067573 | I41: =I40/H40-1 -> -0.088249605 | J41: =J40/I40-1 -> -0.85495877 | K41: =K40/J40-1 -> 4.666326 | L41: =('DCF Model'!K30*'DCF Model'!K53)/'DCF Model'!J51-1 -> 0.048706069 | M41: =('DCF Model'!L30*'DCF Model'!L53)/('DCF Model'!K30*'DCF Model'!K53)-1 -> 0.14298304 | N41: =('DCF Model'!M30*'DCF Model'!M53)/('DCF Model'!L30*'DCF Model'!L53)-1 -> 0.10274939 | O41: =('DCF Model'!N30*'DCF Model'!N53)/('DCF Model'!M30*'DCF Model'!M53)-1 -> 0.11015367 | P41: =('DCF Model'!O30*'DCF Model'!O53)/('DCF Model'!N30*'DCF Model'!N53)-1 -> 0.10659836 | Q41: =('DCF Model'!P30*'DCF Model'!P53)/('DCF Model'!O30*'DCF Model'!O53)-1 -> 0.16944845

Sheet BS
A1: BALANCE SHEET
B3: ticker | C3: yearReport | D3: CURRENT ASSETS (Bn. VND) | E3: Cash and cash equivalents (Bn. VND) | F3: Short-term investments (Bn. VND) | G3: Accounts receivable (Bn. VND) | H3: Net Inventories | I3: Other current assets | J3: LONG-TERM ASSETS (Bn. VND) | K3: Long-term loans receivables (Bn. VND) | L3: Fixed assets (Bn. VND) | M3: Long-term investments (Bn. VND) | N3: Goodwill | O3: Other non-current assets | P3: TOTAL ASSETS (Bn. VND) | Q3: LIABILITIES (Bn. VND) | R3: Current liabilities (Bn. VND) | S3: Long-term liabilities (Bn. VND) | T3: OWNER'S EQUITY(Bn.VND) | U3: Capital and reserves (Bn. VND) | V3: Other Reserves | W3: Undistributed earnings (Bn. VND) | X3: MINORITY INTERESTS | Y3: TOTAL RESOURCES (Bn. VND) | Z3: Prepayments to suppliers (Bn. VND) | AA3: Short-term loans receivables (Bn. VND) | AB3: Inventories, Net (Bn. VND) | AC3: Other current assets (Bn. VND) | AD3: Common shares (Bn. VND) | AE3: Paid-in capital (Bn. VND) | AF3: Long-term borrowings (Bn. VND) | AG3: Advances from customers (Bn. VND) | AH3: Short-term borrowings (Bn. VND) | AI3: Good will (Bn. VND) | AJ3: Long-term prepayments (Bn. VND) | AK3: Other long-term receivables (Bn. VND) | AL3: Long-term trade receivables (Bn. VND)
A4: 1 | B4: MWG | C4: 2013 | D4: 1909084643229 | E4: 304733768468 | F4: 0 | G4: 247310873457 | H4: 1288949605087 | I4: 68090396217 | J4: 322791455377 | K4: 0 | L4: 275039772239 | M4: 0 | N4: 698432896 | O4: 47053250242 | P4: 2231876098606 | Q4: 1407239941555 | R4: 1407239941555 | S4: 0 | T4: 800283880305 | U4: 800283880305 | V4: 1130494084 | W4: 538007977935 | X4: 0 | Y4: 2231876098606 | Z4: 37945761587 | AA4: 0 | AB4: 1304678340679 | AC4: 2954626383 | AD4: 109567040000 | AE4: 109567040000 | AF4: 0 | AG4: 1565912107 | AH4: 513188993447 | AI4: 0 | AJ4: 5395418925 | AK4: 0 | AL4: 0
A5: 2 | B5: MWG | C5: 2014 | D5: 2837686622393 | E5: 212920620191 | F5: 0 | G5: 296735549237 | H5: 2195306348135 | I5: 132724104830 | J5: 569512868791 | K5: 0 | L5: 434419261598 | M5: 0 | N5: 22546549264 | O5: 112547057929 | P5: 3407199491184 | Q5: 1923190326673 | R5: 1923190326673 | S5: 0 | T5: 1474956147637 | U5: 1474956147637 | V5: 1130494084 | W5: 317840559767 | X5: 0 | Y5: 3407199491184 | Z5: 90846398087 | AA5: 0 | AB5: 2253516929935 | AC5: 5217189550 | AD5: 1119567790000 | AE5: 1119567790000 | AF5: 0 | AG5: 8353792068 | AH5: 618690305273 | AI5: 0 | AJ5: 25459480409 | AK5: 0 | AL5: 0
A6: 3 | B6: MWG | C6: 2015 | D6: 6176432326364 | E6: 343872968705 | F6: 0 | G6: 636322979955 | H6: 4932684842299 | I6: 263551535405 | J6: 1089329907510 | K6: 0 | L6: 849146989686 | M6: 0 | N6: 0 | O6: 84864286742 | P6: 7265762233874 | Q6: 4782209545548 | R6: 4782209545548 | S6: 0 | T6: 2483552688326 | U6: 2483552688326 | V6: 1130494084 | W6: 977630195800 | X6: 1638854656 | Y6: 7265762233874 | Z6: 218453419175 | AA6: 0 | AB6: 5009708492628 | AC6: 0 | AD6: 1468889740000 | AE6: 1468889740000 | AF6: 0 | AG6: 19297585840 | AH6: 2052945972681 | AI6: 12525860700 | AJ6: 56933695976 | AK6: 112464049268 | AL6: 112464049268
A7: 4 | B7: MWG | C7: 2016 | D7: 12288439407269 | E7: 996983462012 | F7: 0 | G7: 1410642874572 | H7: 9370731749778 | I7: 510081320907 | J7: 2565823825722 | K7: 0 | L7: 2096126249031 | M7: 0 | N7: 0 | O7: 209591839137 | P7: 14854263232991 | Q7: 11012905506628 | R7: 11012905506628 | S7: 0 | T7: 3841357726363 | U7: 3841357726363 | V7: 1130494084 | W7: 2261763398339 | X7: 2316030154 | Y7: 14854263232991 | Z7: 315210181153 | AA7: 0 | AB7: 9513657569828 | AC7: 0 | AD7: 1539509270000 | AE7: 1539509270000 | AF7: 0 | AG7: 20044459341 | AH7: 4788991746757 | AI7: 0 | AJ7: 123544885549 | AK7: 179685175407 | AL7: 179685175407
A8: 4 | B8: MWG | C8: 2017 | D8: 18862861306281 | E8: 3410983351393 | F8: 0 | G8: 2765847815554 | H8: 12050162650982 | I8: 635867488352 | J8: 3959802908939 | K8: 0 | L8: 3463657994935 | M8: 0 | N8: 0 | O8: 218571537101 | P8: 22822664215220 | Q8: 16913747880005 | R8: 15713814885175 | S8: 1199932994830 | T8: 5908916335215 | U8: 5908916335215 | V8: 1130494084 | W8: 2698572748459 | X8: 2776252251 | Y8: 22822664215220 | Z8: 117942038760 | AA8: 84700000000 | AB8: 12309955461929 | AC8: 0 | AD8: 3169884370000 | AE8: 3169884370000 | AF8: 1199932994830 | AG8: 22475498439 | AH8: 5603505990526 | AI8: 0 | AJ8: 97701063493 | AK8: 242115970118 | AL8: 242115970118
A9: 6 | B9: MWG | C9: 2018 | D9: 23371994756394 | E9: 3749550258212 | F9: 50922451739 | G9: 1542529736073 | H9: 17446005298981 | I9: 582987011389 | J9: 4750536730462 | K9: 0 | L9: 3333147659602 | M9: 59937763115 | N9: 0 | O9: 786843665206 | P9: 28122531486856 | Q9: 19139496155514 | R9: 17929433003626 | S9: 1210063151888 | T9: 8983035331342 | U9: 8983035331342 | V9: 1130494084 | W9: 3989603910055 | X9: 6249443319 | Y9: 28122531486856 | Z9: 21007291749 | AA9: 0 | AB9: 17821137643753 | AC9: 0 | AD9: 4434961780000 | AE9: 4434961780000 | AF9: 1208167140389 | AG9: 38061594053 | AH9: 5836454637089 | AI9: 552526849066 | AJ9: 84768088475 | AK9: 313775645332 | AL9: 313775645332
A10: 7 | B10: MWG | C10: 2019 | D10: 35011896908246 | E10: 3115236816468 | F10: 3137000000000 | G10: 1815085561979 | H10: 25745428436580 | I10: 1199146093219 | J10: 6696198636637 | K10: 0 | L10: 5403776988921 | M10: 56464479744 | N10: 0 | O10: 773963131188 | P10: 41708095544883 | Q10: 29564503350530 | R10: 28442366683873 | S10: 1122136666657 | T10: 12143592194353 | U10: 12143592194353 | V10: 1130494084 | W10: 7149694161602 | X10: 7786065614 | Y10: 41708095544883 | Z10: 195016846986 | AA10: 0 | AB10: 26195934673884 | AC10: 0 | AD10: 4435461780000 | AE10: 4435461780000 | AF10: 1122136666657 | AG10: 81194129529 | AH10: 13031015620192 | AI10: 491134976947 | AJ10: 104029473910 | AK10: 374563598474 | AL10: 374563598474
A11: 8 | B11: MWG | C11: 2020 | D11: 37317233970267 | E11: 7347857397925 | F11: 8057318821918 | G11: 1595251018496 | H11: 19422177452674 | I11: 894629279254 | J11: 8713645982187 | K11: 0 | L11: 7294961666136 | M11: 52757540273 | N11: 0 | O11: 793813155551 | P11: 46030879952454 | Q11: 30549190106022 | R11: 29422513439369 | S11: 1126676666653 | T11: 15481689846432 | U11: 15481689846432 | V11: 0 | W11: 10389683597845 | X11: 9280633826 | Y11: 46030879952454 | Z11: 287913331552 | AA11: 80000000000 | AB11: 19926363502365 | AC11: 0 | AD11: 4532099870000 | AE11: 4532099870000 | AF11: 1126676666653 | AG11: 86907353149 | AH11: 15625180321924 | AI11: 429743104828 | AJ11: 76720247019 | AK11: 439493257757 | AL11: 439493257757
A12: 9 | B12: MWG | C12: 2021 | D12: 51955257770657 | E12: 4142015762555 | F12: 14236626334707 | G12: 3162121971586 | H12: 29167232293922 | I12: 1247261407887 | J12: 11016147044285 | K12: 0 | L12: 9647168873232 | M12: 0 | N12: 0 | O12: 806891052417 | P12: 62971404814942 | Q12: 42593158815096 | R12: 42593158815096 | S12: 0 | T12: 20378245999846 | U12: 20378245999846 | V12: 0 | W12: 12674574164065 | X12: 11838029496 | Y12: 62971404814942 | Z12: 390738782756 | AA12: 961917697638 | AB12: 29850068817719 | AC12: 0 | AD12: 7130654950000 | AE12: 7130654950000 | AF12: 0 | AG12: 98379250626 | AH12: 24647474278786 | AI12: 368351232709 | AJ12: 88371396963 | AK12: 482389179464 | AL12: 482389179464
A13: 10 | B13: MWG | C13: 2022 | D13: 44577607228189 | E13: 5061020547422 | F13: 10069249605640 | G13: 3000817466182 | H13: 25696077735282 | I13: 750441873663 | J13: 11256488385860 | K13: 9744723329 | L13: 9727502911440 | M13: 231034840000 | N13: 0 | O13: 670590081979 | P13: 55834095614049 | Q13: 31901514096473 | R13: 26000264096473 | S13: 5901250000000 | T13: 23932581517576 | U13: 23932581517576 | V13: 0 | W13: 8723934226370 | X13: 14508097130 | Y13: 55834095614049 | Z13: 403669438496 | AA13: 16917697638 | AB13: 26058131396686 | AC13: 0 | AD13: 14638792800000 | AE13: 14638792800000 | AF13: 5901250000000 | AG13: 97659957856 | AH13: 10688138631456 | AI13: 306959360590 | AJ13: 175104437161 | AK13: 493741850234 | AL13: 503486573563
A14: 12 | B14: MWG | C14: 2023 | D14: 51950337976047 | E14: 5365704857172 | F14: 18937008073823 | G14: 5158853337785 | H14: 21824235626176 | I14: 664536081091 | J14: 8160899236677 | K14: 9244973329 | L14: 6500135608914 | M14: 746632252729 | N14: 0 | O14: 452067531470 | P14: 60111237212724 | Q14: 36751679245386 | R14: 30765260553972 | S14: 5986418691414 | T14: 23359557967338 | U14: 23359557967338 | V14: 0 | W14: 8160323595574 | X14: 13401030472 | Y14: 60111237212724 | Z14: 95981093251 | AA14: 2085917697638 | AB14: 22028684523096 | AC14: 0 | AD14: 14633767160000 | AE14: 14633767160000 | AF14: 5985250000000 | AG14: 88995836420 | AH14: 19128541817781 | AI14: 245567488471 | AJ14: 105411103799 | AK14: 448325013301 | AL14: 457569986630
A15: 13 | B15: MWG | C15: 2024 | D15: 65836422620040 | E15: 4897331540730 | F15: 29324441756320 | G15: 8825896224771 | H15: 22244676326705 | I15: 544076771514 | J15: 4601353101564 | K15: 0 | L15: 3586628664045 | M15: 242035797830 | N15: 0 | O15: 358454413877 | P15: 70437775721604 | Q15: 42316198897749 | R15: 42316198897749 | S15: 0 | T15: 28121576823855 | U15: 28121576823855 | V15: 0 | W15: 12582145266842 | X15: 364020651398 | Y15: 70437775721604 | Z15: 115888383111 | AA15: 6037714596101 | AB15: 22667774012643 | AC15: 0 | AD15: 14622441770000 | AE15: 14622441770000 | AF15: 0 | AG15: 90966314915 | AH15: 27300246721779 | AI15: 0 | AJ15: 68471833530 | AK15: 389707802472 | AL15: 389707802472

Sheet IS
A1: INCOME STATEMENT
B3: ticker | C3: yearReport | D3: Revenue YoY (%) | E3: Revenue (Bn. VND) | F3: Attribute to parent company (Bn. VND) | G3: Attribute to parent company YoY (%) | H3: Financial Income | I3: Interest Expenses | J3: Sales | K3: Sales deductions | L3: Net Sales | M3: Cost of Sales | N3: Gross Profit | O3: Financial Expenses | P3: Gain/(loss) from joint ventures | Q3: Selling Expenses | R3: General & Admin Expenses | S3: Operating Profit/Loss | T3: Other income | U3: Other Income/Expenses | V3: Net other income/expenses | W3: Profit before tax | X3: Business income tax - current | Y3: Business income tax - deferred | Z3: Net Profit For the Year | AA3: Minority Interest | AB3: Attributable to parent company
A4: 0 | B4: MWG | C4: 2013 | D4: 0 | E4: 9544540892171 | F4: 255601250424 | G4: 0 | H4: 29466115268 | I4: -26535371431 | J4: 9544540892171 | K4: -45691574828 | L4: 9498849317343 | M4: -8091484102566 | N4: 1407365214777 | O4: -26843253776 | P4: 0 | Q4: -935793711279 | R4: -125646424308 | S4: 348547940682 | T4: 10158134968 | U4: -7918446086 | V4: 2239688882 | W4: 350787629564 | X4: -92541582226 | Y4: 222806148 | Z4: 258468853486 | AA4: 2867603062 | AB4: 255601250424
A5: 1 | B5: MWG | C5: 2014 | D5: 0.65923636 | E5: 15836649248254 | F5: 668106031832 | G5: 1.6138606 | H5: 71335314202 | I5: -21261415761 | J5: 15836649248254 | K5: -79923391578 | L5: 15756725856676 | M5: -13360606457365 | N5: 2396119399311 | O5: -21291413996 | P5: 0 | Q5: -1349301070370 | R5: -240543267438 | S5: 856318961709 | T5: 15118039591 | U5: -3239558206 | V5: 11878481385 | W5: 868197443094 | X5: -203799232655 | Y5: 9346006165 | Z5: 673744216604 | AA5: 5638184772 | AB5: 668106031832
A6: 2 | B6: MWG | C6: 2015 | D6: 0.60312144 | E6: 25388072018730 | F6: 1071893519399 | G6: 0.60437635 | H6: 80985820413 | I6: -38893852014 | J6: 25388072018730 | K6: -135338939486 | L6: 25252733079244 | M6: -21330302185370 | N6: 3922430893874 | O6: -40666093756 | P6: 0 | Q6: -2351094719997 | R6: -249315306535 | S6: 1362340593999 | T6: 25192750122 | U6: -1749556427 | V6: 23443193695 | W6: 1385783787694 | X6: -312610960322 | Y6: 2598402071 | Z6: 1075771229443 | AA6: 3877710044 | AB6: 1071893519399
A7: 3 | B7: MWG | C7: 2016 | D7: 0.79661838 | E7: 45612676802016 | F7: 1577372426339 | G7: 0.47157567 | H7: 135327700732 | I7: -119645695306 | J7: 45612676802016 | K7: -999344129028 | L7: 44613332672988 | M7: -37399226360426 | N7: 7214106312562 | O7: -120085861346 | P7: 0 | Q7: -4287696260226 | R7: -934776941124 | S7: 2006874950598 | T7: 31129990083 | U7: -32090825758 | V7: -960835675 | W7: 2005914114923 | X7: -495800545472 | Y7: 68137051386 | Z7: 1578250620837 | AA7: 878194498 | AB7: 1577372426339
A8: 4 | B8: MWG | C8: 2017 | D8: 0.48420451 | E8: 67698540686709 | F8: 2205679630420 | G8: 0.39832521 | H8: 250509808127 | I8: -233202340492 | J8: 67698540686709 | K8: -1358736494531 | L8: 66339804192178 | M8: -55198024925235 | N8: 11141779266943 | O8: -234286596275 | P8: 0 | Q8: -7017061321366 | R8: -1345497381559 | S8: 2795443775870 | T8: 17684643400 | U8: -3816386624 | V8: 13868256776 | W8: 2809312032646 | X8: -639743605453 | Y8: 37328692156 | Z8: 2206897119349 | AA8: 1217488929 | AB8: 2205679630420
A9: 5 | B9: MWG | C9: 2018 | D9: 0.29601581 | E9: 87738378978636 | F9: 2878724130908 | G9: 0.30514155 | H9: 342083875229 | I9: -436416577674 | J9: 87738378978636 | K9: -1222091976137 | L9: 86516287002499 | M9: -71224159239435 | N9: 15292127763064 | O9: -436573150236 | P9: -2100986885 | Q9: -9659741188756 | R9: -1761613900080 | S9: 3774182412336 | T9: 33233337382 | U9: -21097180799 | V9: 12136156583 | W9: 3786318568919 | X9: -933836738446 | Y9: 27827229661 | Z9: 2880309060134 | AA9: 1584929226 | AB9: 2878724130908
A10: 6 | B10: MWG | C10: 2019 | D10: 0.17947297 | E10: 103485046672447 | F10: 3834269547047 | G10: 0.33193365 | H10: 631177854351 | I10: -568136717134 | J10: 103485046672447 | K10: -1310802695724 | L10: 102174243976723 | M10: -82686444673012 | N10: 19487799303711 | O10: -569754844844 | P10: -3473283371 | Q10: -12437282718212 | R10: -2073782880058 | S10: 5034683431577 | T10: 41557041541 | U10: -22793268422 | V10: 18763773119 | W10: 5053447204696 | X10: -1248353081834 | Y10: 31145964165 | Z10: 3836240087027 | AA10: 1970539980 | AB10: 3834269547047
A11: 7 | B11: MWG | C11: 2020 | D11: 0.061034973 | E11: 109801253690656 | F11: 3917767783159 | G11: 0.02177683 | H11: 794121782667 | I11: -594003821021 | J11: 109801253690656 | K11: -1255234025244 | L11: 108546019665412 | M11: -84591522392949 | N11: 23954497272463 | O11: -594151513751 | P11: -3706939471 | Q11: -15333798830787 | R11: -3404431838167 | S11: 5412529932954 | T11: 43512695471 | U11: -46307221072 | V11: -2794525601 | W11: 5409735407353 | X11: -1598413821219 | Y11: 108551123373 | Z11: 3919872709507 | AA11: 2104926348 | AB11: 3917767783159
A12: 8 | B12: MWG | C12: 2021 | D12: 0.13060208 | E12: 124141525689948 | F12: 4898869278220 | G12: 0.2504236 | H12: 1287956026163 | I12: -674427746189 | J12: 124141525689948 | K12: -1183419586774 | L12: 122958106103174 | M12: -95325974107640 | N12: 27632131995534 | O12: -714707225745 | P12: -2210500486 | Q12: -17914173302345 | R12: -3823390074765 | S12: 6465606918356 | T12: 54872797433 | U12: -48895965246 | V12: 5976832187 | W12: 6471583750543 | X12: -1632975695694 | Y12: 62818619041 | Z12: 4901426673890 | AA12: 2557395670 | AB12: 4898869278220
A13: 9 | B13: MWG | C13: 2022 | D13: 0.085231136 | E13: 134722248887557 | F13: 4099763027305 | G13: -0.16312055 | H13: 1313137304323 | I13: -1362143909103 | J13: 134722248887557 | K13: -1317471297033 | L13: 133404777590524 | M13: -102542735094343 | N13: 30862042496181 | O13: -1382620454532 | P13: 0 | Q13: -22336838067678 | R13: -1881027579714 | S13: 6574693698580 | T13: 61606712681 | U13: -579945037703 | V13: -518338325022 | W13: 6056355373558 | X13: -1792998810102 | Y13: -161642138517 | Z13: 4101714424939 | AA13: 1951397634 | AB13: 4099763027305
A14: 10 | B14: MWG | C14: 2023 | D14: -0.11496293 | E14: 119234184825086 | F14: 167669392704 | G14: -0.95910266 | H14: 2166963715091 | I14: -1447718354797 | J14: 119234184825086 | K14: -954396369644 | L14: 118279788455442 | M14: -95759175291712 | N14: 22520613163730 | O14: -1556146106982 | P14: 0 | Q14: -20916710755306 | R14: -1167651662536 | S14: 1047068353997 | T14: 36883419051 | U14: -394259405152 | V14: -357375986101 | W14: 689692367896 | X14: -433257176515 | Y14: -88606036442 | Z14: 167829154939 | AA14: 159762235 | AB14: 167669392704
A15: 11 | B15: MWG | C15: 2024 | D15: 0.13411352 | E15: 135225101298992 | F15: 3721868441661 | G15: 21.197662 | H15: 2376502605263 | I15: -1137236129748 | J15: 135225101298992 | K15: -883948450190 | L15: 134341152848802 | M15: -106841942771781 | N15: 27499210077021 | O15: -1188465609510 | P15: -44596454899 | Q15: -19849837609882 | R15: -3565767583102 | S15: 5227045424891 | T15: 25743895664 | U15: -427026307477 | V15: -401282411813 | W15: 4825763013078 | X15: -1282537116919 | Y15: 190062332561 | Z15: 3733288228720 | AA15: 11419787059 | AB15: 3721868441661

Sheet CF
A1: CASHFLOW STATEMENT
B3: ticker | C3: yearReport | D3: Net Profit/Loss before tax | E3: Depreciation and Amortisation | F3: Provision for credit losses | G3: Unrealized foreign exchange gain/loss | H3: Profit/Loss from investing activities | I3: Interest Expense | J3: Operating profit before changes in working capital | K3: Increase/Decrease in receivables | L3: Increase/Decrease in inventories | M3: Increase/Decrease in payables | N3: Increase/Decrease in prepaid expenses | O3: Changes in Working Capital | P3: Interest paid | Q3: Business Income Tax paid | R3: Other payments on operating activities | S3: Net cash inflows/outflows from operating activities | T3: Purchase of fixed assets | U3: Proceeds from disposal of fixed assets | V3: Loans granted, purchases of debt instruments (Bn. VND) | W3: Collection of loans, proceeds from sales of debts instruments (Bn. VND) | X3: Investment in other entities | Y3: Proceeds from divestment in other entities | Z3: Gain on Dividend | AA3: Net Cash Flows from Investing Activities | AB3: Increase in charter captial | AC3: Payments for share repurchases | AD3: Proceeds from borrowings | AE3: Repayment of borrowings | AF3: Dividends paid | AG3: Cash flows from financial activities | AH3: Net increase/decrease in cash and cash equivalents | AI3: Cash and cash equivalents | AJ3: Foreign exchange differences Adjustment | AK3: Cash and Cash Equivalents at the end of period
A4: 0 | B4: MWG | C4: 2013 | D4: 350787629564 | E4: 34254161373 | F4: 2778672865 | G4: 0 | H4: 201097567 | I4: 26535371431 | J4: 414556932800 | K4: -116625906539 | L4: -340163891869 | M4: 129409197568 | N4: 101125017946 | O4: =-(K4)-(L4)+(M4)-(N4) -> 485073978030 | P4: -26262404801 | Q4: -58109616672 | R4: 0 | S4: 103929328433 | T4: -142189977899 | U4: 4573757305 | V4: 0 | W4: 0 | X4: 0 | Y4: 19950000000 | Z4: 3002270118 | AA4: -114663950476 | AB4: 108850459021 | AC4: -20057078735 | AD4: 3616870963398 | AE4: -3495027300214 | AF4: 0 | AG4: 210637043470 | AH4: 199902421427 | AI4: 104831347041 | AJ4: 0 | AK4: 304733768468
A5: 1 | B5: MWG | C5: 2014 | D5: 868197443094 | E5: 116388450156 | F5: 50319643793 | G5: 0 | H5: -4921557749 | I5: 21261415761 | J5: 1051245395055 | K5: -69681219038 | L5: -948838589256 | M5: 415275921603 | N5: -69527740506 | O5: =-(K5)-(L5)+(M5)-(N5) -> 1503323470403 | P5: -21122048282 | Q5: -221553246030 | R5: -36133740038 | S5: 99664733508 | T5: -266396524598 | U5: 1447928974 | V5: 0 | W5: 0 | X5: -50000000000 | Y5: 0 | Z5: 6723644862 | AA5: -308224950762 | AB5: 14163663481 | AC5: -300394500 | AD5: 3786869312765 | AE5: -3681368000939 | AF5: -2617511830 | AG5: 116747068977 | AH5: -91813148277 | AI5: 304733768468 | AJ5: 0 | AK5: 212920620191
A6: 2 | B6: MWG | C6: 2015 | D6: 1385783787694 | E6: 197056011824 | F6: 32187455819 | G6: -138916487 | H6: -856415030 | I6: 38893852014 | J6: 1652925775834 | K6: -476685311770 | L6: -2756191562693 | M6: 1235357266488 | N6: -63386564833 | O6: =-(K6)-(L6)+(M6)-(N6) -> 4531620705784 | P6: -37442521379 | Q6: -196048457727 | R6: 0 | S6: -641471376080 | T6: -586517897472 | U6: 0 | V6: 0 | W6: 0 | X6: -72239580000 | Y6: 0 | Z6: 913660286 | AA6: -657843817186 | AB6: 0 | AC6: -2153900000 | AD6: 8129261915021 | AE6: -6695006247613 | AF6: -1834225628 | AG6: 1430267541780 | AH6: 130952348514 | AI6: 212920620191 | AJ6: 0 | AK6: 343872968705
A7: 3 | B7: MWG | C7: 2016 | D7: 2005914114923 | E7: 386634522356 | F7: 78431491258 | G7: -91382580 | H7: 2261763 | I7: 119645695306 | J7: 2590536703026 | K7: -989517728630 | L7: -4503949077200 | M7: 3124564571480 | N7: -164867267201 | O7: =-(K7)-(L7)+(M7)-(N7) -> 8782898644511 | P7: -112394627462 | Q7: -530854203913 | R7: 0 | S7: -586481629900 | T7: -1278788918537 | U7: 951588323 | V7: 0 | W7: 0 | X7: 0 | Y7: 0 | Z7: 1799386697 | AA7: -1276037943517 | AB7: 0 | AC7: -315300000 | AD7: 19961551061988 | AE7: -17225505287912 | AF7: -220130282800 | AG7: 2515600191276 | AH7: 653080617859 | AI7: 343872968705 | AJ7: 29875448 | AK7: 996983462012
A8: 4 | B8: MWG | C8: 2017 | D8: 2809312032646 | E8: 689713708632 | F8: 125969042598 | G8: 911764559 | H8: -35336741307 | I8: 233202340492 | J8: 3823772147620 | K8: -1322949244960 | L8: -2796297892101 | M8: 3970336761157 | N8: -96805747662 | O8: =-(K8)-(L8)+(M8)-(N8) -> 8186389645880 | P8: -223723867627 | Q8: -690668199572 | R8: 0 | S8: 2663663956855 | T8: -2065069567410 | U8: 180000000 | V8: -210280000000 | W8: 125580000000 | X8: 0 | Y8: 0 | Z8: 29374580928 | AA8: -2120214986482 | AB8: 92466480000 | AC8: 0 | AD8: 29465789268692 | AE8: -27456000269116 | AF8: -231718927130 | AG8: 1870536552446 | AH8: 2413985522819 | AI8: 996983462012 | AJ8: 14366562 | AK8: 3410983351393
A9: 5 | B9: MWG | C9: 2018 | D9: 3786318568918 | E9: 1222868683717 | F9: 126083626828 | G9: -107059306 | H9: -84857279584 | I9: 436416577674 | J9: 5486723118247 | K9: 1246646823981 | L9: -4672944194460 | M9: 1331042865781 | N9: 126753313780 | O9: =-(K9)-(L9)+(M9)-(N9) -> 4630586922480 | P9: -427564376510 | Q9: -829523019750 | R9: 0 | S9: 2261134531069 | T9: -1495931919038 | U9: 1339965525 | V9: -85922451739 | W9: 0 | X9: -828166470141 | Y9: 0 | Z9: 64286835061 | AA9: -2344394040332 | AB9: 705355067201 | AC9: -729700000 | AD9: 31893805156672 | AE9: -31690848740269 | AF9: -485862426828 | AG9: 421719356776 | AH9: 338459847513 | AI9: 3410983351393 | AJ9: 107059306 | AK9: 3749550258212
A10: 6 | B10: MWG | C10: 2019 | D10: 5053447204696 | E10: 1442826938954 | F10: 90495782206 | G10: -27160364 | H10: -341194613832 | I10: 568136717134 | J10: 6813684868794 | K10: -675979882201 | L10: -8374797030131 | M10: 2823942311184 | N10: -227805034461 | O10: =-(K10)-(L10)+(M10)-(N10) -> 12102524257977 | P10: -537997464046 | Q10: -1092128547184 | R10: -15000000000 | S10: -1286080778045 | T10: -3066921164140 | U10: 1290807344 | V10: -8997469863015 | W10: 5911392314754 | X10: 0 | Y10: 0 | Z10: 278946264804 | AA10: -5872761640253 | AB10: 90454820000 | AC10: -4850060000 | AD10: 45905952301242 | AE10: -38801961791867 | AF10: -665093453185 | AG10: 6524501816190 | AH10: -634340602108 | AI10: 3749550258212 | AJ10: 27160364 | AK10: 3115236816468
A11: 7 | B11: MWG | C11: 2020 | D11: 5409735407353 | E11: 2195583071035 | F11: 58366659386 | G11: -36874578 | H11: -557627148536 | I11: 594003821021 | J11: 7700024935681 | K11: 850493238036 | L11: 6269571171519 | M11: -1894206905085 | N11: -75119169600 | O11: =-(K11)-(L11)+(M11)-(N11) -> -8939152145040 | P11: -563748612045 | Q11: -1494585439732 | R11: 0 | S11: 10792429218774 | T11: -3911358160002 | U11: 2018075304 | V11: -11512468958904 | W11: 6512150136986 | X11: 0 | Y11: 0 | Z11: 335398013989 | AA11: -8574260892627 | AB11: 105200450000 | AC11: -6040930000 | AD11: 51168161383884 | AE11: -48573996682152 | AF11: -678908841000 | AG11: 2014415380732 | AH11: 4232583706879 | AI11: 3115236816468 | AJ11: 36874578 | AK11: 7347857397925
A12: 8 | B12: MWG | C12: 2021 | D12: 6471583750543 | E12: 2920713608410 | F12: 179550717177 | G12: -146653994 | H12: -959323580633 | I12: 674427746189 | J12: 9286805587692 | K12: -827596105467 | L12: -9923705315353 | M12: 3781614904801 | N12: -27490477725 | O12: =-(K12)-(L12)+(M12)-(N12) -> 14560406803346 | P12: -585136035219 | Q12: -1533102122807 | R12: 0 | S12: 171390435922 | T12: -4976876590016 | U12: 1107020670 | V12: -19225219180045 | W12: 12163993969618 | X12: -16385001737 | Y12: 796626468011 | Z12: 1883709063 | AA12: -11254869604436 | AB12: 228253030000 | AC12: -2320000000 | AD12: 63936208247950 | AE12: -56045130957737 | AF12: -239519441063 | AG12: 7877490879150 | AH12: -3205988289364 | AI12: 7347857397925 | AJ12: 146653994 | AK12: 4142015762555
A13: 9 | B13: MWG | C13: 2022 | D13: 6056355373558 | E13: 3540324726294 | F13: -321799366884 | G13: 284374414 | H13: -348599792355 | I13: 1362143909103 | J13: 10288709224130 | K13: -588827639446 | L13: 3791937421033 | M13: -2286756979213 | N13: -101041271147 | O13: =-(K13)-(L13)+(M13)-(N13) -> -5388825489653 | P13: -1322381109404 | Q13: -1805340844308 | R13: 0 | S13: 7976298801645 | T13: -4465359523505 | U13: 5331159526 | V13: -20799334065331 | W13: 25851966071069 | X13: -181034840000 | Y13: 0 | Z13: 1137542621557 | AA13: 1549111423316 | AB13: 192628370000 | AC13: -5025640000 | AD13: 65251647851081 | AE13: -73313739286999 | AF13: -731854815000 | AG13: -8606343520918 | AH13: 919066704043 | AI13: 4142015762555 | AJ13: -61919176 | AK13: 5061020547422
A14: 10 | B14: MWG | C14: 2023 | D14: 689692367896 | E14: 3351314267883 | F14: -165930068132 | G14: 83631272202 | H14: -1509203341265 | I14: 1447718354797 | J14: 3897222853381 | K14: 672440536688 | L14: 4169031757473 | M14: -3136706601092 | N14: 130000103455 | O14: =-(K14)-(L14)+(M14)-(N14) -> -8108178998708 | P14: -1435731870616 | Q14: -860429603219 | R14: 0 | S14: 3435827176070 | T14: -523383330794 | U14: 31276790650 | V14: -34151374180637 | W14: 22805115462454 | X14: -105597412729 | Y14: 0 | Z14: 1112667974114 | AA14: -10831294696942 | AB14: 443220000 | AC14: -9783280000 | AD14: 70373733043570 | AE14: -61933329857245 | AF14: -731280023500 | AG14: 7699783102825 | AH14: 304315581953 | AI14: 5061020547422 | AJ14: 368727797 | AK14: 5365704857172
A15: 11 | B15: MWG | C15: 2024 | D15: 4825763013078 | E15: 2913419081483 | F15: 220952651591 | G15: 25689580954 | H15: -1729164103487 | I15: 1137236129748 | J15: 7393896353367 | K15: 151205190961 | L15: -636927914305 | M15: 3581806724649 | N15: 127788870902 | O15: =-(K15)-(L15)+(M15)-(N15) -> 3939740577091 | P15: -1141521540734 | Q15: -958914978098 | R15: 0 | S15: 8517332706742 | T15: -303747827395 | U15: 54661690191 | V15: -52159250994595 | W15: 38289265386964 | X15: 0 | Y15: 0 | Z15: 2375786074417 | AA15: -11743285670418 | AB15: 1771634338542 | AC15: -9141790000 | AD15: 74756279079533 | AE15: -73030338420383 | AF15: -730957694000 | AG15: 2757475513692 | AH15: -468477449984 | AI15: 5365704857172 | AJ15: 104133542 | AK15: 4897331540730

Sheet Breakdown by Segments
A2: REVENUE BREAKDOWN BY SEGMENTS (Billion VND)
A3: Source: Investor Relation Monthly Report of MWG
B5: TGDD | C5: Dien May Xanh | D5: BHX | E5: Other Revenues | F5: Total Net Revenue
A6: 43465 | B6: =86516*40% -> 34606.4 | C6: =86516*55% -> 47583.8 | D6: =86516*5% -> 4325.8 | F6: =SUM(B6:E6) -> 86516
A7: 43830 | B7: =102174*32.5% -> 33206.55 | C7: =102174*57% -> 58239.18 | D7: =102174*10.5% -> 10728.27 | F7: =SUM(B7:E7) -> 102174
A8: 44196 | B8: =108546*27.2% -> 29524.512 | C8: =108546*53.2% -> 57746.472 | D8: =108546*19.6% -> 21275.016 | F8: =SUM(B8:E8) -> 108546
A9: 44561 | B9: =122958*25.7% -> 31600.206 | C9: =122958*51% -> 62708.58 | D9: =122958*22.9% -> 28157.382 | E9: =122958*0.4% -> 491.832 | F9: =SUM(B9:E9) -> 122958
A10: 44926 | B10: =133405*26% -> 34685.3 | C10: =133405*51.7% -> 68970.385 | D10: =133405*20.3% -> 27081.215 | E10: =133405*2% -> 2668.1 | F10: =SUM(B10:E10) -> 133405
A11: 45291 | B11: =118280*23.9% -> 28268.92 | C11: =118280*46.7% -> 55236.76 | D11: =118280*26.7% -> 31580.76 | E11: =118280*2.7% -> 3193.56 | F11: =SUM(B11:E11) -> 118280
A12: 45657 | B12: =134341*22.4% -> 30092.384 | C12: =134341*44.3% -> 59513.063 | D12: =134341*30.6% -> 41108.346 | E12: =134341*2.7% -> 3627.207 | F12: =SUM(B12:E12) -> 134341
A13: 45961 | B13: =128289*23.7% -> 30404.493 | C13: =128289*44% -> 56447.16 | D13: =128289*30% -> 38486.7 | E13: =128289*2.3% -> 2950.647 | F13: =SUM(B13:E13) -> 128289
A16: NUMBER OF STORES BREAKDOWN BY SEGMENTS
B18: TGDD | C18: Dien May Xanh | D18: BHX | E18: Other Stores | F18: Total Stores
A19: 43465 | B19: 1032 | C19: 750 | D19: 405 | E19: 0 | F19: =SUM(B19:E19) -> 2187
A20: 43830 | B20: 996 | C20: 1018 | D20: 1008 | E20: 12 | F20: =SUM(B20:E20) -> 3034
A21: 44196 | B21: 913 | C21: 1427 | D21: 1719 | E21: =F21-B21-C21-D21 -> 0 | F21: 4059
A22: 44561 | B22: 970 | C22: 1992 | D22: 2106 | E22: =F22-B22-C22-D22 -> 238 | F22: 5306
A23: 44926 | B23: 1190 | C23: 2284 | D23: 1728 | E23: 564 | F23: =B23+C23+D23+E23 -> 5766
A24: 45291 | B24: 1078 | C24: 2190 | D24: 1698 | E24: =527+64+38 -> 629 | F24: =SUM(B24:E24) -> 5595
A25: 45657 | B25: 1021 | C25: 2026 | D25: 1770 | E25: =326+62+87 -> 475 | F25: =SUM(B25:E25) -> 5292
A26: 45961 | B26: 1012 | C26: 2017 | D26: 2370 | E26: =356+72+158 -> 586 | F26: =SUM(B26:E26) -> 5985

Sheet DCF Model
D2: 2018 | E2: =D2+1 -> 2019 | F2: =E2+1 -> 2020 | G2: =F2+1 -> 2021 | H2: =G2+1 -> 2022 | I2: =H2+1 -> 2023 | J2: =I2+1 -> 2024 | K2: =J2+1 -> 2025 | L2: =K2+1 -> 2026 | ... P2: =O2+1 -> 2030
B3: MWG DCF model
B5: OVERVIEW
B6: Company ticker | C6: MWG
B7: Date | C7: =TODAY() -> 45983
B8: Year-end | C8: 46022
B9: Stock price | C9: 80000
B10: Stock price forecast | C10: =P89 -> 91098.757
B11: Upside | C11: =C10/C9 -1 -> 0.13873446
B12: Judgement of valuation | C12: =IF(C11>0, "Undervalued", "Overvalued") -> Undervalued
B14: ASSUMPTION
B16: Scenario | E16: 1. Pessimistic case | H16: 2. Base case | K16: 3. Optimistic case
B17: Case selected | C17: 2 | E17: Revenue g % | F17: 0.9 | K17: Revenue g% | L17: 1.05
B18: WACC | C18: =CHOOSE($C$17,F18,I18,L18) -> 0.10620794 | E18: WACC | F18: =I18+0.5% -> 0.11120794 | H18: WACC | I18: =WACC!C25 -> 0.10620794 | K18: WACC | L18: =I18-0.3% -> 0.10320794
B19: Terminal Growth Rate | C19: =CHOOSE($C$17,F19,I19,L19) -> 0.068 | E19: Terminal Growth Rate | F19: =I19-0.5% -> 0.063 | H19: Terminal Growth Rate | I19: 0.068 | K19: Terminal Growth Rate | L19: =I19+0.3% -> 0.071
B21: Revenue breakdown
B22: TGDD Revenue | D22: 34606.4 | E22: 33206.55 | F22: 29524.512 | G22: 31507.686 | H22: 34685.3 | I22: 28268.92 | J22: 30092.384 | K22: =J22*(1+K23:P23) -> 29571.809 | L22: =K22*(1+L23:Q23) -> 29174.345 | M22: =L22*(1+M23:R23) -> 29256.025 | N22: =M22*(1+N23:S23) -> 29024.062 | O22: =N22*(1+O23:T23) -> 28267.728 | P22: =O22*(1+P23:U23) -> 28279.867
B23: %growth | E23: =E22/D22-1 -> -0.04045061 | F23: =F22/E22-1 -> -0.11088288 | G23: =G22/F22-1 -> 0.067170424 | H23: =H22/G22-1 -> 0.10085203 | I23: =I22/H22-1 -> -0.18498845 | J23: =J22/I22-1 -> 0.064504198 | K23: =AVERAGE(E23:J23) -> -0.017299216 | L23: =AVERAGE(F23:K23) -> -0.013440651 | M23: =AVERAGE(G23:L23) -> 0.0027997214 | N23: =AVERAGE(H23:M23) -> -0.007928729 | O23: =AVERAGE(I23:N23) -> -0.026058855 | P23: =AVERAGE(J23:O23) -> 0.00042941133
B24: DMX Revenue | D24: 47583.8 | E24: 58239.18 | F24: 57746.472 | G24: 62524.98 | H24: 68970.385 | I24: 55236.76 | J24: 59513.063 | K24: =J24*(1+K25) -> 62286.351 | L24: =K24*(1+L25) -> 63348.01 | M24: =L24*(1+M25) -> 64697.045 | N24: =M24*(1+N25) -> 65412.158 | O24: =N24*(1+O25) -> 65131.84 | P24: =O24*(1+P25) -> 66967.75
B25: %growth | E25: =E24/D24-1 -> 0.22392873 | F25: =F24/E24-1 -> -0.0084600779 | G25: =G24/F24-1 -> 0.082749783 | H25: =H24/G24-1 -> 0.10308528 | I25: =I24/H24-1 -> -0.19912351 | J25: =J24/I24-1 -> 0.077417702 | K25: =AVERAGE(E25:J25) -> 0.046599652 | L25: =AVERAGE(F25:K25) -> 0.017044805 | M25: =AVERAGE(G25:L25) -> 0.021295619 | N25: =AVERAGE(H25:M25) -> 0.011053258 | O25: =AVERAGE(I25:N25) -> -0.0042854123 | P25: =AVERAGE(J25:O25) -> 0.028187604
B26: BHX Revenue | D26: 4325.8 | E26: 10728.27 | F26: 21275.016 | G26: 28074.942 | H26: 30683.15 | I26: 31580.76 | J26: 41108.346 | K26: =J26*(1+K27) -> 63078.096 | L26: =K26*(1+L27) -> 86847.822 | M26: =L26*(1+M27) -> 110799.45 | N26: =M26*(1+N27) -> 140547.25 | O26: =N26*(1+O27) -> 182394.74 | P26: =O26*(1+P27) -> 244864.13
B27: %growth | E27: =E26/D26-1 -> 1.4800661 | F27: =F26/E26-1 -> 0.98307984 | G27: =G26/F26-1 -> 0.31962025 | H27: =H26/G26-1 -> 0.092901634 | I27: =I26/H26-1 -> 0.029254167 | J27: =J26/I26-1 -> 0.30168957 | K27: =AVERAGE(E27:J27) -> 0.53443526 | L27: =AVERAGE(F27:K27) -> 0.37683012 | M27: =AVERAGE(G27:L27) -> 0.2757885 | N27: =AVERAGE(H27:M27) -> 0.26848321 | O27: =AVERAGE(I27:N27) -> 0.29774681 | P27: =AVERAGE(J27:O27) -> 0.34249558
B29: INCOME STATEMENT
B30: Total Revenue | D30: {=TRANSPOSE(IS!E9:E15)} -> 87738378978636 | E30: 103485046672447 | F30: 109801253690656 | G30: 124141525689948 | H30: 134722248887557 | I30: 119234184825086 | J30: 135225101298992 | K30: =SUM(K22,K24,K26)*10^9 -> 1.5493626e+14 | L30: =SUM(L22,L24,L26)*10^9 -> 1.7937018e+14 | M30: =SUM(M22,M24,M26)*10^9 -> 2.0475252e+14 | N30: =SUM(N22,N24,N26)*10^9 -> 2.3498347e+14 | O30: =SUM(O22,O24,O26)*10^9 -> 2.7579431e+14 | P30: =SUM(P22,P24,P26)*10^9 -> 3.4011175e+14
B31: % growth | E31: =E30/D30-1 -> 0.17947297 | F31: =F30/E30-1 -> 0.061034973 | G31: =G30/F30-1 -> 0.13060208 | H31: =H30/G30-1 -> 0.085231136 | I31: =I30/H30-1 -> -0.11496293 | J31: =J30/I30-1 -> 0.13411352 | K31: =CHOOSE($C$17,K35,K36,K37) -> 0.1457655 | L31: =CHOOSE($C$17,L35,L36,L37) -> 0.15770305 | M31: =CHOOSE($C$17,M35,M36,M37) -> 0.14150817 | N31: =CHOOSE($C$17,N35,N36,N37) -> 0.14764625 | O31: =CHOOSE($C$17,O35,O36,O37) -> 0.17367538 | P31: =CHOOSE($C$17,P35,P36,P37) -> 0.23320801
B33: Net Revenue | D33: {=TRANSPOSE(IS!L9:L15)} -> 86516287002499 | E33: 102174243976723 | F33: 108546019665412 | G33: 122958106103174 | H33: 133404777590524 | I33: 118279788455442 | J33: 134341152848802 | K33: =J33*(1+K36) -> 1.5392346e+14 | L33: =K33*(1+L36) -> 1.7819766e+14 | M33: =L33*(1+M36) -> 2.0341408e+14 | N33: =M33*(1+N36) -> 2.3344741e+14 | O33: =N33*(1+O36) -> 2.7399148e+14 | P33: =O33*(1+P36) -> 3.3788848e+14
B34: % growth | E34: =E33/D33 -1 -> 0.18098277 | F34: =F33/E33 -1 -> 0.062361858 | G34: =G33/F33 -1 -> 0.13277397 | H34: =H33/G33 -1 -> 0.084961226 | I34: =I33/H33 -1 -> -0.11337667 | J34: =J33/I33 -1 -> 0.13579128 | K34: =CHOOSE($C$17,K35,K36,K37) -> 0.1457655 | L34: =CHOOSE($C$17,L35,L36,L37) -> 0.15770305 | M34: =CHOOSE($C$17,M35,M36,M37) -> 0.14150817 | N34: =CHOOSE($C$17,N35,N36,N37) -> 0.14764625 | O34: =CHOOSE($C$17,O35,O36,O37) -> 0.17367538 | P34: =CHOOSE($C$17,P35,P36,P37) -> 0.23320801
B35: Pessimistic Case | K35: =$F$17*K36 -> 0.13118895 | L35: =$F$17*L36 -> 0.14193275 | M35: =$F$17*M36 -> 0.12735736 | N35: =$F$17*N36 -> 0.13288163 | O35: =$F$17*O36 -> 0.15630784 | P35: =$F$17*P36 -> 0.20988721
B36: Base Case | K36: =K30/J30-1 -> 0.1457655 | L36: =L30/K30-1 -> 0.15770305 | M36: =M30/L30-1 -> 0.14150817 | N36: =N30/M30-1 -> 0.14764625 | O36: =O30/N30-1 -> 0.17367538 | P36: =P30/O30-1 -> 0.23320801
B37: Optimistic Case | K37: =$L$17*K36 -> 0.15305378 | L37: =$L$17*L36 -> 0.16558821 | M37: =$L$17*M36 -> 0.14858358 | N37: =$L$17*N36 -> 0.15502857 | O37: =$L$17*O36 -> 0.18235915 | P37: =$L$17*P36 -> 0.24486841
B39: Gross Profit | D39: {=TRANSPOSE(IS!N9:N15)} -> 15292127763064 | E39: 19487799303711 | F39: 23954497272463 | G39: 27632131995534 | H39: 30862042496181 | I39: 22520613163730 | J39: 27499210077021 | K39: =K30*K40 -> 3.1533301e+13 | L39: =L30*L40 -> 3.725525e+13 | M39: =M30*M40 -> 4.3094197e+13 | N39: =N30*N40 -> 4.9198658e+13 | O39: =O30*O40 -> 5.7222593e+13 | P39: =P30*P40 -> 6.9518059e+13
B40: % sales | D40: =D39/D30 -> 0.17429234 | E40: =E39/E30 -> 0.18831512 | F40: =F39/F30 -> 0.21816233 | G40: =G39/G30 -> 0.22258573 | H40: =H39/H30 -> 0.22907903 | I40: =I39/I30 -> 0.18887715 | J40: =J39/J30 -> 0.20335877 | K40: =AVERAGE(D40:J40) -> 0.20352435 | L40: =AVERAGE(E40:K40) -> 0.20770036 | M40: =AVERAGE(F40:L40) -> 0.21046967 | N40: =AVERAGE(G40:M40) -> 0.20937072 | O40: =AVERAGE(H40:N40) -> 0.20748287 | P40: =AVERAGE(I40:O40) -> 0.2043977
B42: EBIT | D42: {=TRANSPOSE(IS!S9:S15)} -> 3774182412336 | E42: 5034683431577 | F42: 5412529932954 | G42: 6465606918356 | H42: 6574693698580 | I42: 1047068353997 | J42: 5227045424891 | K42: =K30*K43 -> 6.4028939e+12 | L42: =L30*L43 -> 7.3693362e+12 | M42: =M30*M43 -> 8.1908258e+12 | N42: =N30*N43 -> 9.0883025e+12 | O42: =O30*O43 -> 1.0138524e+13 | P42: =P30*P43 -> 1.1917884e+13
B43: % sales | D43: =D42/D30 -> 0.043016323 | E43: =E42/E30 -> 0.048651313 | F43: =F42/F30 -> 0.049293881 | G43: =G42/G30 -> 0.052082548 | H43: =H42/H30 -> 0.04880184 | I43: =I42/I30 -> 0.008781612 | J43: =J42/J30 -> 0.038654402 | K43: =CHOOSE($C$17,K44,K45,K46) -> 0.041325988 | L43: =CHOOSE($C$17,L44,L45,L46) -> 0.041084512 | M43: =CHOOSE($C$17,M44,M45,M46) -> 0.040003541 | N43: =CHOOSE($C$17,N44,N45,N46) -> 0.038676349 | O43: =CHOOSE($C$17,O44,O45,O46) -> 0.036761178 | P43: =CHOOSE($C$17,P44,P45,P46) -> 0.035041083
B44: Pessimistic Case | K44: =K45*$F$17 -> 0.03719339 | L44: =L45*$F$17 -> 0.036976061 | M44: =M45*$F$17 -> 0.036003186 | N44: =N45*$F$17 -> 0.034808714 | O44: =O45*$F$17 -> 0.03308506 | P44: =P45*$F$17 -> 0.031536975
B45: Base Case | K45: =AVERAGE(D43:J43) -> 0.041325988 | L45: =AVERAGE(E43:K43) -> 0.041084512 | M45: =AVERAGE(F43:L43) -> 0.040003541 | N45: =AVERAGE(G43:M43) -> 0.038676349 | O45: =AVERAGE(H43:N43) -> 0.036761178 | P45: =AVERAGE(I43:O43) -> 0.035041083
B46: Optimistic Case | K46: =K45*$L$17 -> 0.043392288 | L46: =L45*$L$17 -> 0.043138738 | M46: =M45*$L$17 -> 0.042003718 | N46: =N45*$L$17 -> 0.040610166 | O46: =O45*$L$17 -> 0.038599237 | P46: =P45*$L$17 -> 0.036793137
B48: Taxes | D48: {=ABS(TRANSPOSE(IS!X9:X15))} -> 933836738446 | E48: 1248353081834 | F48: 1598413821219 | G48: 1632975695694 | H48: 1792998810102 | I48: 433257176515 | J48: 1282537116919 | K48: =K42*K49 -> 1.8066386e+12 | L48: =L42*L49 -> 2.1158943e+12 | M48: =M42*M49 -> 2.397596e+12 | N48: =N42*N49 -> 2.6569272e+12 | O48: =O42*O49 -> 3.0215742e+12 | P48: =P42*P49 -> 3.5949786e+12
B49: % Tax rate | D49: =D48/D42 -> 0.24742756 | E49: =E48/E42 -> 0.24795066 | F49: =F48/F42 -> 0.29531732 | G49: =G48/G42 -> 0.2525634 | H49: =H48/H42 -> 0.27271214 | I49: =I48/I42 -> 0.41378118 | J49: =J48/J42 -> 0.2453656 | K49: =AVERAGE(D49:J49) -> 0.28215969 | L49: =AVERAGE(E49:K49) -> 0.28712143 | M49: =AVERAGE(F49:L49) -> 0.29271725 | N49: =AVERAGE(G49:M49) -> 0.29234581 | O49: =AVERAGE(H49:N49) -> 0.29802901 | P49: =AVERAGE(I49:O49) -> 0.30164571
B51: NOPAT | D51: =D42-D48 -> 2840345673890 | E51: =E42-E48 -> 3786330349743 | F51: =F42-F48 -> 3814116111735 | G51: =G42-G48 -> 4832631222662 | H51: =H42-H48 -> 4781694888478 | I51: =I42-I48 -> 613811177482 | J51: =J42-J48 -> 3944508307972 | K51: =K30*K52 -> 4.5962553e+12 | L51: =L30*L52 -> 5.2534419e+12 | M51: =M30*M52 -> 5.7932298e+12 | N51: =N30*N52 -> 6.4313753e+12 | O51: =O30*O52 -> 7.1169494e+12 | P51: =P30*P52 -> 8.3229055e+12
...

Sheet WACC
B2: WACC Calculation
B4: Formula used
B5: Wacc = Re * E/V + Rd*(1-t)*D/V
B6: Re = Rf + Be*(MRP)
B7: V = D + E
B10: Items | C10: Value | D10: Source
B11: Market Equity | C11: =121972 -> 121972 | D11: Vietstock
B12: Debt | C12: =27300+5986 -> 33286 | D12: Up to Q3/2024 audit report by EY
B13: Value(E+D) | C13: =SUM(C11:C12) -> 155258 | D13: Vietstock
B14: E/V | C14: =C11/SUM(C11:C12) -> 0.78560847 | D14: Vietstock
B15: D/V | C15: =C12/SUM(C11:C12) -> 0.21439153 | D15: Vietstock
B17: Re | C17: =(C18+(C19*C20)) -> 0.124276
B18: Rf | C18: 0.040036 | D18: 10-year government bond yield curve
B19: Bequity | C19: 1.08 | D19: yahoofinance
B20: MRP | C20: 0.078 | D20: Based on research of VNDIRECT
B22: Rd | C22: 0.05 | D22: Based on MBS research
B23: 1-t | C23: 0.8 | D23: Corporate tax rate: 20%
B25: WACC | C25: =C14*C17 + C15*C22*C23 -> 0.10620794

Sheet Competitor Analysis
B1: Comparable Companies Analysis
D3: Market Data | H3: Financials | L3: Valuation
B4: Company | C4: Ticker | D4: Share Price (in VND) | E4: Market Cap (in millions VND) | F4: Enterprise Value (in Trillions VND) | H4: Revenue | I4: EBITDA | J4: Net Income | L4: EV/Revenue | M4: EV/EBITDA | N4: Forward P/E
B5: ICT-CE Company
B6: FPT Retail | C6: FRT | D6: 147000 | E6: 25034 | F6: 27.86 | H6: =40241629282059 -> 40241629282059 | I6: 1098828869000 | J6: 317516265000 | L6: 0.59 | M6: 16.25 | N6: 26.95
B7: Digiworld Corporation | C7: DGW | D7: 43500 | E7: 9620 | F7: 12.29 | H7: 22078832142000 | I7: 720257904000 | J7: 443877018000 | L7: 0.5 | M7: 14.4 | N7: 14.88
B8: Retail Consumer Company
B9: Masan Consumers | C9: MSN | D9: 78800 | E9: 114230 | F9: 159.03 | H9: 83177720000 | I9: 16562464000 | J9: 1999059000 | L9: 1.96 | M9: 9.28 | N9: 24.1
B10: Walmart | C10: WMT US | L10: 1.25 | M10: 19.37 | N10: 33.56
B11: Ryohin | C11: 7453 JP | L11: 1.94 | M11: 15.1 | N11: 17.99
B14: MWG Valuation
B15: Implied Enterprise Value (Trillion) | D15: 161.52
B16: EV/Revenue | D16: ='DCF Model'!P85/'DCF Model'!K30 -> 1.042542
B17: EV/EBITDA | D17: ='DCF Model'!P88/('DCF Model'!K42+'DCF Model'!K77) -> 13.776917
B18: Shares Outstanding | D18: 1461484209
B19: Implied Forward P/E | D19: ='DCF Model'!P89/('DCF Model'!L60/'DCF Model'!J89) -> 34.501135
B20: Implied Price | D20: ='DCF Model'!C10 -> 91098.757
B21: Actual Price | D21: ='DCF Model'!C9 -> 80000
B23: Comment: MWG has higher valuations among the competitors
B26: MWG Current Market Status
B27: Implied Enterprise Value (Trillion) | D27: 119.75
B28: EV/Revenue | D28: 0.74
B29: EV/EBITDA | D29: 6.86
B30: Shares Outstanding | D30: 1461484209
B31: Forward P/E | D31: 16.34
